Workbook

Sheet W-1
A4: GL01- CH/B
B8: BOX SASH WINDOW | H8: Timber Section | I8: Finished Length | J8: Number | K8: TRENCH DEPTH | O8: Sapele
G9: HEAD | H9: 28 x 141 | I9: =B21 -> 920 | J9: 1 | K9: 11mm | O9: 1.5 inch x 150 | P9: =I9+(I10*2) -> 2588 | Q9: =(P9*1.15)/1000 -> 2.9762
G10: JAMBS | H10: 28 x 141 | I10: =C21-106 -> 834 | J10: 2 | K10: N/A | O10: 1 inch x 120 | P10: =I12+I13+(I14*2)+(I15*2) -> 5226 | Q10: =(P10*1.15)/1000 -> 6.0099
G11: CILL | H11: 69 X 46/46.7 X 127 | I11: =B21 -> 920 | J11: 1 | K11: 37mm | O11: 75x50 | P11: =I11 -> 920 | Q11: =(P11*1.15)/1000 -> 1.058
G12: EXTERNAL HEAD LINER | H12: 17 X 102 | I12: =B21-204 -> 716 | J12: 1 | K12: N/A | O12: 125x60 | P12: =I11 -> 920 | Q12: =(P12*1.15)/1000 -> 1.058
A13: WITH HORNS TO TOP SASH ONLY | G13: INTERNAL HEAD LINER | H13: 17 X 85 | I13: =B21-170 -> 750 | J13: 1 | K13: N/A
G14: EXTERNAL JAMB LINER | H14: 17 X 102 | I14: =C21 -> 940 | J14: 2 | K14: N/A
G15: INTERNAL JAMB LINER | H15: 17 X 86 | I15: =C21 -> 940 | J15: 2 | K15: N/A
H16: Timber section | I16: Finished Length | J16: Number | K16: TENON LENGTH | L16: SLOT LENGTH | O16: RED GRANDIS
G17: TOP RAIL | H17: 57 X 57mm | I17: =B24 -> 742 | J17: 1 | K17: 39mm & 57mm | L17: N/A | O17: 63X63 | P17: =(I17*J17)+(I18*J18)+(I19*J19)+I21+I22 -> 4062 | Q17: =(P17*1.15)/1000 -> 4.6713
G18: STILES TOP SASH | H18: 57 X 57mm | I18: =D24 -> 477.5 | J18: 2 | K18: N/A | L18: TOP 39mm BOTTOM MORTICE | O18: 63X95 | P18: =I20 -> 742 | Q18: =(P18*1.1)/1000 -> 0.8162
B19: NON BAR | G19: STILES BOTTOM SASH | H19: 57 X 57mm | I19: =C25 -> 440.5 | J19: 2 | K19: N/A | L19: TOP 25mm BOTTOM 72mm
B20: FRAME WIDTH | C20: FRAME HEIGHT | G20: BOTTOM RAIL | H20: 57 X 90mm | I20: =B24 -> 742 | J20: 1 | K20: 39mm & 57mm | L20: N/A
B21: 920 | C21: 940 | G21: TOP MEET RAIL | H21: 57 X 43mm | I21: =B24 -> 742 | J21: 1 | K21: 39mm & 57mm | L21: N/A
G22: BOTTOM MEET RAIL | H22: 57 X 43mm | I22: =B25 -> 742 | J22: 1 | K22: 39mm & 57mm | L22: N/A
B23: SASH WIDTH | C23: SASH HEIGHT | D23: SASH HEIGHT WITH HORN
A24: TOP SASH | B24: =B21-178 -> 742 | C24: =C21/2+(-62.5) -> 407.5 | D24: =C24+70 -> 477.5 | E24: 1no SASH | G24: TRICKLE VENT | H24: YES | I24: NO | J24: CONCEALED
A25: BOTTOM SASH | B25: =B21-178 -> 742 | C25: =C21/2+(-29.5) -> 440.5 | D25: N/A | E25: 1no SASH | G25: SASH CATCHES | H25: PAS24 | I25: NON PAS24
B26: GLASS WIDTH | C26: GLASS HEIGHT | G26: GLASS | H26: 24mm | I26: TGH/ARG/TGH | J26: Obscure | K26: Others?
B27: =B24-114+24 -> 652 | C27: =C24-100+24 -> 331.5 | D27: 1no UNIT | G27: GLASS | H27: 24.8mm | I27: LAM/ARG/TGH | J27: Obscure | K27: Others?
B28: =B25-114+24 -> 652 | C28: =C25-133+24 -> 331.5 | D28: 1no UNIT | G28: HARDWARE FINISH | H28: BRASS | I28: POL CHROME | J28: SATIN | K28: Others?
G29: CILL EXTENSION | H29: 35mm | I29: 60mm | J29: 85mm | K29: 110mm
G30: PAINT | H30: RAL | I30: ?
K32: TOTAL
G33: PRICE | H33: 1500 | I33: VAT 20% | J33: =H33*20% -> 300 | K33: =H33+J33 -> 1800

Sheet W-2
A4: GL02-JAM
B8: BOX SASH WINDOW | H8: Timber Section | I8: Finished Length | J8: Number | K8: TRENCH DEPTH | O8: Sapele
G9: HEAD | H9: 28 x 141 | I9: =B21 -> 1070 | J9: 1 | K9: 11mm | O9: 1.5 inch x 150 | P9: =I9+(I10*2) -> 4308 | Q9: =(P9*1.15)/1000 -> 4.9542
G10: JAMBS | H10: 28 x 141 | I10: =C21-106 -> 1619 | J10: 2 | K10: N/A | O10: 1 inch x 120 | P10: =I12+I13+(I14*2)+(I15*2) -> 8666 | Q10: =(P10*1.15)/1000 -> 9.9659
G11: CILL | H11: 69 X 46/46.7 X 127 | I11: =B21 -> 1070 | J11: 1 | K11: 37mm | O11: 75x50 | P11: =I11 -> 1070 | Q11: =(P11*1.15)/1000 -> 1.2305
G12: EXTERNAL HEAD LINER | H12: 17 X 102 | I12: =B21-204 -> 866 | J12: 1 | K12: N/A | O12: 125x60 | P12: =I11 -> 1070 | Q12: =(P12*1.15)/1000 -> 1.2305
A13: WITH HORNS TO TOP SASH ONLY | G13: INTERNAL HEAD LINER | H13: 17 X 85 | I13: =B21-170 -> 900 | J13: 1 | K13: N/A
G14: EXTERNAL JAMB LINER | H14: 17 X 102 | I14: =C21 -> 1725 | J14: 2 | K14: N/A
G15: INTERNAL JAMB LINER | H15: 17 X 86 | I15: =C21 -> 1725 | J15: 2 | K15: N/A
H16: Timber section | I16: Finished Length | J16: Number | K16: TENON LENGTH | L16: SLOT LENGTH | O16: RED GRANDIS
G17: TOP RAIL | H17: 57 X 57mm | I17: =B24 -> 892 | J17: 1 | K17: 39mm & 57mm | L17: N/A | O17: 63X63 | P17: =(I17*J17)+(I18*J18)+(I19*J19)+I21+I22 -> 6082 | Q17: =(P17*1.15)/1000 -> 6.9943
G18: STILES TOP SASH | H18: 57 X 57mm | I18: =D24 -> 870 | J18: 2 | K18: N/A | L18: TOP 39mm BOTTOM MORTICE | O18: 63X95 | P18: =I20 -> 892 | Q18: =(P18*1.1)/1000 -> 0.9812
B19: NON BAR | G19: STILES BOTTOM SASH | H19: 57 X 57mm | I19: =C25 -> 833 | J19: 2 | K19: N/A | L19: TOP 25mm BOTTOM 72mm
B20: FRAME WIDTH | C20: FRAME HEIGHT | G20: BOTTOM RAIL | H20: 57 X 90mm | I20: =B24 -> 892 | J20: 1 | K20: 39mm & 57mm | L20: N/A
B21: 1070 | C21: 1725 | G21: TOP MEET RAIL | H21: 57 X 43mm | I21: =B24 -> 892 | J21: 1 | K21: 39mm & 57mm | L21: N/A
G22: BOTTOM MEET RAIL | H22: 57 X 43mm | I22: =B25 -> 892 | J22: 1 | K22: 39mm & 57mm | L22: N/A
B23: SASH WIDTH | C23: SASH HEIGHT | D23: SASH HEIGHT WITH HORN
A24: TOP SASH | B24: =B21-178 -> 892 | C24: =C21/2+(-62.5) -> 800 | D24: =C24+70 -> 870 | E24: 1no SASH | G24: TRICKLE VENT | H24: YES | I24: NO | J24: CONCEALED
A25: BOTTOM SASH | B25: =B21-178 -> 892 | C25: =C21/2+(-29.5) -> 833 | D25: N/A | E25: 1no SASH | G25: SASH CATCHES | H25: PAS24 | I25: NON PAS24
B26: GLASS WIDTH | C26: GLASS HEIGHT | G26: GLASS | H26: 24mm | I26: TGH/ARG/TGH | J26: Obscure | K26: Others?
B27: =B24-114+24 -> 802 | C27: =C24-100+24 -> 724 | D27: 1no UNIT | G27: GLASS | H27: 24.8mm | I27: LAM/ARG/TGH | J27: Obscure | K27: Others?
B28: =B25-114+24 -> 802 | C28: =C25-133+24 -> 724 | D28: 1no UNIT | G28: HARDWARE FINISH | H28: BRASS | I28: POL CHROME | J28: SATIN | K28: Others?
G29: CILL EXTENSION | H29: 35mm | I29: 60mm | J29: 85mm | K29: 110mm
G30: PAINT | H30: RAL | I30: ?
K32: TOTAL
G33: PRICE | H33: 1500 | I33: VAT 20% | J33: =H33*20% -> 300 | K33: =H33+J33 -> 1800

Sheet W-3
A4: GL03-JAM
B8: BOX SASH WINDOW | H8: Timber Section | I8: Finished Length | J8: Number | K8: TRENCH DEPTH | O8: Sapele
G9: HEAD | H9: 28 x 141 | I9: =B21 -> 1050 | J9: 1 | K9: 11mm | O9: 1.5 inch x 150 | P9: =I9+(I10*2) -> 4228 | Q9: =(P9*1.15)/1000 -> 4.8622
G10: JAMBS | H10: 28 x 141 | I10: =C21-106 -> 1589 | J10: 2 | K10: N/A | O10: 1 inch x 120 | P10: =I12+I13+(I14*2)+(I15*2) -> 8506 | Q10: =(P10*1.15)/1000 -> 9.7819
G11: CILL | H11: 69 X 46/46.7 X 127 | I11: =B21 -> 1050 | J11: 1 | K11: 37mm | O11: 75x50 | P11: =I11 -> 1050 | Q11: =(P11*1.15)/1000 -> 1.2075
G12: EXTERNAL HEAD LINER | H12: 17 X 102 | I12: =B21-204 -> 846 | J12: 1 | K12: N/A | O12: 125x60 | P12: =I11 -> 1050 | Q12: =(P12*1.15)/1000 -> 1.2075
A13: WITH HORNS TO TOP SASH ONLY | G13: INTERNAL HEAD LINER | H13: 17 X 85 | I13: =B21-170 -> 880 | J13: 1 | K13: N/A
G14: EXTERNAL JAMB LINER | H14: 17 X 102 | I14: =C21 -> 1695 | J14: 2 | K14: N/A
G15: INTERNAL JAMB LINER | H15: 17 X 86 | I15: =C21 -> 1695 | J15: 2 | K15: N/A
H16: Timber section | I16: Finished Length | J16: Number | K16: TENON LENGTH | L16: SLOT LENGTH | O16: RED GRANDIS
G17: TOP RAIL | H17: 57 X 57mm | I17: =B24 -> 872 | J17: 1 | K17: 39mm & 57mm | L17: N/A | O17: 63X63 | P17: =(I17*J17)+(I18*J18)+(I19*J19)+I21+I22 -> 5962 | Q17: =(P17*1.15)/1000 -> 6.8563
G18: STILES TOP SASH | H18: 57 X 57mm | I18: =D24 -> 855 | J18: 2 | K18: N/A | L18: TOP 39mm BOTTOM MORTICE | O18: 63X95 | P18: =I20 -> 872 | Q18: =(P18*1.1)/1000 -> 0.9592
B19: NON BAR | G19: STILES BOTTOM SASH | H19: 57 X 57mm | I19: =C25 -> 818 | J19: 2 | K19: N/A | L19: TOP 25mm BOTTOM 72mm
B20: FRAME WIDTH | C20: FRAME HEIGHT | G20: BOTTOM RAIL | H20: 57 X 90mm | I20: =B24 -> 872 | J20: 1 | K20: 39mm & 57mm | L20: N/A
B21: 1050 | C21: 1695 | G21: TOP MEET RAIL | H21: 57 X 43mm | I21: =B24 -> 872 | J21: 1 | K21: 39mm & 57mm | L21: N/A
G22: BOTTOM MEET RAIL | H22: 57 X 43mm | I22: =B25 -> 872 | J22: 1 | K22: 39mm & 57mm | L22: N/A
B23: SASH WIDTH | C23: SASH HEIGHT | D23: SASH HEIGHT WITH HORN
A24: TOP SASH | B24: =B21-178 -> 872 | C24: =C21/2+(-62.5) -> 785 | D24: =C24+70 -> 855 | E24: 1no SASH | G24: TRICKLE VENT | H24: YES | I24: NO | J24: CONCEALED
A25: BOTTOM SASH | B25: =B21-178 -> 872 | C25: =C21/2+(-29.5) -> 818 | D25: N/A | E25: 1no SASH | G25: SASH CATCHES | H25: PAS24 | I25: NON PAS24
B26: GLASS WIDTH | C26: GLASS HEIGHT | G26: GLASS | H26: 24mm | I26: TGH/ARG/TGH | J26: Obscure | K26: Others?
B27: =B24-114+24 -> 782 | C27: =C24-100+24 -> 709 | D27: 1no UNIT | G27: GLASS | H27: 24.8mm | I27: LAM/ARG/TGH | J27: Obscure | K27: Others?
B28: =B25-114+24 -> 782 | C28: =C25-133+24 -> 709 | D28: 1no UNIT | G28: HARDWARE FINISH | H28: BRASS | I28: POL CHROME | J28: SATIN | K28: Others?
G29: CILL EXTENSION | H29: 35mm | I29: 60mm | J29: 85mm | K29: 110mm
G30: PAINT | H30: RAL | I30: ?
K32: TOTAL
G33: PRICE | H33: 1500 | I33: VAT 20% | J33: =H33*20% -> 300 | K33: =H33+J33 -> 1800

Sheet W-4
A4: GL04-JAM
B8: BOX SASH WINDOW | H8: Timber Section | I8: Finished Length | J8: Number | K8: TRENCH DEPTH | O8: Sapele
G9: HEAD | H9: 28 x 141 | I9: =B21 -> 1240 | J9: 1 | K9: 11mm | O9: 1.5 inch x 150 | P9: =I9+(I10*2) -> 4758 | Q9: =(P9*1.15)/1000 -> 5.4717
G10: JAMBS | H10: 28 x 141 | I10: =C21-106 -> 1759 | J10: 2 | K10: N/A | O10: 1 inch x 120 | P10: =I12+I13+(I14*2)+(I15*2) -> 9566 | Q10: =(P10*1.15)/1000 -> 11.0009
G11: CILL | H11: 69 X 46/46.7 X 127 | I11: =B21 -> 1240 | J11: 1 | K11: 37mm | O11: 75x50 | P11: =I11 -> 1240 | Q11: =(P11*1.15)/1000 -> 1.426
G12: EXTERNAL HEAD LINER | H12: 17 X 102 | I12: =B21-204 -> 1036 | J12: 1 | K12: N/A | O12: 125x60 | P12: =I11 -> 1240 | Q12: =(P12*1.15)/1000 -> 1.426
A13: WITH HORNS TO TOP SASH ONLY | G13: INTERNAL HEAD LINER | H13: 17 X 85 | I13: =B21-170 -> 1070 | J13: 1 | K13: N/A
G14: EXTERNAL JAMB LINER | H14: 17 X 102 | I14: =C21 -> 1865 | J14: 2 | K14: N/A
G15: INTERNAL JAMB LINER | H15: 17 X 86 | I15: =C21 -> 1865 | J15: 2 | K15: N/A
H16: Timber section | I16: Finished Length | J16: Number | K16: TENON LENGTH | L16: SLOT LENGTH | O16: RED GRANDIS
G17: TOP RAIL | H17: 57 X 57mm | I17: =B24 -> 1062 | J17: 1 | K17: 39mm & 57mm | L17: N/A | O17: 63X63 | P17: =(I17*J17)+(I18*J18)+(I19*J19)+I21+I22 -> 6872 | Q17: =(P17*1.15)/1000 -> 7.9028
G18: STILES TOP SASH | H18: 57 X 57mm | I18: =D24 -> 940 | J18: 2 | K18: N/A | L18: TOP 39mm BOTTOM MORTICE | O18: 63X95 | P18: =I20 -> 1062 | Q18: =(P18*1.1)/1000 -> 1.1682
B19: NON BAR | G19: STILES BOTTOM SASH | H19: 57 X 57mm | I19: =C25 -> 903 | J19: 2 | K19: N/A | L19: TOP 25mm BOTTOM 72mm
B20: FRAME WIDTH | C20: FRAME HEIGHT | G20: BOTTOM RAIL | H20: 57 X 90mm | I20: =B24 -> 1062 | J20: 1 | K20: 39mm & 57mm | L20: N/A
B21: 1240 | C21: 1865 | G21: TOP MEET RAIL | H21: 57 X 43mm | I21: =B24 -> 1062 | J21: 1 | K21: 39mm & 57mm | L21: N/A
G22: BOTTOM MEET RAIL | H22: 57 X 43mm | I22: =B25 -> 1062 | J22: 1 | K22: 39mm & 57mm | L22: N/A
B23: SASH WIDTH | C23: SASH HEIGHT | D23: SASH HEIGHT WITH HORN
A24: TOP SASH | B24: =B21-178 -> 1062 | C24: =C21/2+(-62.5) -> 870 | D24: =C24+70 -> 940 | E24: 1no SASH | G24: TRICKLE VENT | H24: YES | I24: NO | J24: CONCEALED
A25: BOTTOM SASH | B25: =B21-178 -> 1062 | C25: =C21/2+(-29.5) -> 903 | D25: N/A | E25: 1no SASH | G25: SASH CATCHES | H25: PAS24 | I25: NON PAS24
B26: GLASS WIDTH | C26: GLASS HEIGHT | G26: GLASS | H26: 24mm | I26: TGH/ARG/TGH | J26: Obscure | K26: Others?
B27: =B24-114+24 -> 972 | C27: =C24-100+24 -> 794 | D27: 1no UNIT | G27: GLASS | H27: 24.8mm | I27: LAM/ARG/TGH | J27: Obscure | K27: Others?
B28: =B25-114+24 -> 972 | C28: =C25-133+24 -> 794 | D28: 1no UNIT | G28: HARDWARE FINISH | H28: BRASS | I28: POL CHROME | J28: SATIN | K28: Others?
G29: CILL EXTENSION | H29: 35mm | I29: 60mm | J29: 85mm | K29: 110mm
G30: PAINT | H30: RAL | I30: ?
K32: TOTAL
G33: PRICE | H33: 1500 | I33: VAT 20% | J33: =H33*20% -> 300 | K33: =H33+J33 -> 1800

Sheet W-5
A4: GL05-JAM
B8: BOX SASH WINDOW | H8: Timber Section | I8: Finished Length | J8: Number | K8: TRENCH DEPTH | O8: Sapele
G9: HEAD | H9: 28 x 141 | I9: =B21 -> 560 | J9: 1 | K9: 11mm | O9: 1.5 inch x 150 | P9: =I9+(I10*2) -> 2798 | Q9: =(P9*1.15)/1000 -> 3.2177
G10: JAMBS | H10: 28 x 141 | I10: =C21-106 -> 1119 | J10: 2 | K10: N/A | O10: 1 inch x 120 | P10: =I12+I13+(I14*2)+(I15*2) -> 5646 | Q10: =(P10*1.15)/1000 -> 6.4929
G11: CILL | H11: 69 X 46/46.7 X 127 | I11: =B21 -> 560 | J11: 1 | K11: 37mm | O11: 75x50 | P11: =I11 -> 560 | Q11: =(P11*1.15)/1000 -> 0.644
G12: EXTERNAL HEAD LINER | H12: 17 X 102 | I12: =B21-204 -> 356 | J12: 1 | K12: N/A | O12: 125x60 | P12: =I11 -> 560 | Q12: =(P12*1.15)/1000 -> 0.644
A13: WITH HORNS TO TOP SASH ONLY | G13: INTERNAL HEAD LINER | H13: 17 X 85 | I13: =B21-170 -> 390 | J13: 1 | K13: N/A
G14: EXTERNAL JAMB LINER | H14: 17 X 102 | I14: =C21 -> 1225 | J14: 2 | K14: N/A
G15: INTERNAL JAMB LINER | H15: 17 X 86 | I15: =C21 -> 1225 | J15: 2 | K15: N/A
H16: Timber section | I16: Finished Length | J16: Number | K16: TENON LENGTH | L16: SLOT LENGTH | O16: RED GRANDIS
G17: TOP RAIL | H17: 57 X 57mm | I17: =B24 -> 382 | J17: 1 | K17: 39mm & 57mm | L17: N/A | O17: 63X63 | P17: =(I17*J17)+(I18*J18)+(I19*J19)+I21+I22 -> 3552 | Q17: =(P17*1.15)/1000 -> 4.0848
G18: STILES TOP SASH | H18: 57 X 57mm | I18: =D24 -> 620 | J18: 2 | K18: N/A | L18: TOP 39mm BOTTOM MORTICE | O18: 63X95 | P18: =I20 -> 382 | Q18: =(P18*1.1)/1000 -> 0.4202
B19: NON BAR | G19: STILES BOTTOM SASH | H19: 57 X 57mm | I19: =C25 -> 583 | J19: 2 | K19: N/A | L19: TOP 25mm BOTTOM 72mm
B20: FRAME WIDTH | C20: FRAME HEIGHT | G20: BOTTOM RAIL | H20: 57 X 90mm | I20: =B24 -> 382 | J20: 1 | K20: 39mm & 57mm | L20: N/A
B21: 560 | C21: 1225 | G21: TOP MEET RAIL | H21: 57 X 43mm | I21: =B24 -> 382 | J21: 1 | K21: 39mm & 57mm | L21: N/A
G22: BOTTOM MEET RAIL | H22: 57 X 43mm | I22: =B25 -> 382 | J22: 1 | K22: 39mm & 57mm | L22: N/A
B23: SASH WIDTH | C23: SASH HEIGHT | D23: SASH HEIGHT WITH HORN
A24: TOP SASH | B24: =B21-178 -> 382 | C24: =C21/2+(-62.5) -> 550 | D24: =C24+70 -> 620 | E24: 1no SASH | G24: TRICKLE VENT | H24: YES | I24: NO | J24: CONCEALED
A25: BOTTOM SASH | B25: =B21-178 -> 382 | C25: =C21/2+(-29.5) -> 583 | D25: N/A | E25: 1no SASH | G25: SASH CATCHES | H25: PAS24 | I25: NON PAS24
B26: GLASS WIDTH | C26: GLASS HEIGHT | G26: GLASS | H26: 24mm | I26: TGH/ARG/TGH | J26: Obscure | K26: Others?
B27: =B24-114+24 -> 292 | C27: =C24-100+24 -> 474 | D27: 1no UNIT | G27: GLASS | H27: 24.8mm | I27: LAM/ARG/TGH | J27: Obscure | K27: Others?
B28: =B25-114+24 -> 292 | C28: =C25-133+24 -> 474 | D28: 1no UNIT | G28: HARDWARE FINISH | H28: BRASS | I28: POL CHROME | J28: SATIN | K28: Others?
G29: CILL EXTENSION | H29: 35mm | I29: 60mm | J29: 85mm | K29: 110mm
G30: PAINT | H30: RAL | I30: ?
K32: TOTAL
G33: PRICE | H33: 1500 | I33: VAT 20% | J33: =H33*20% -> 300 | K33: =H33+J33 -> 1800

Sheet W-6
A4: GL06-JAM-B
B8: BOX SASH WINDOW | E8: FIX | H8: Timber Section | I8: Finished Length | J8: Number | K8: TRENCH DEPTH | O8: Sapele
G9: HEAD | H9: 28 x 141 | I9: =B21 -> 980 | J9: 1 | K9: 11mm | O9: 1.5 inch x 150 | P9: =I9+(I10*2) -> 4418 | Q9: =(P9*1.15)/1000 -> 5.0807
G10: JAMBS | H10: 28 x 141 | I10: =C21-106 -> 1719 | J10: 2 | K10: N/A | O10: 1 inch x 120 | P10: =I12+I13+(I14*2)+(I15*2) -> 8886 | Q10: =(P10*1.15)/1000 -> 10.2189
G11: CILL | H11: 69 X 46/46.7 X 127 | I11: =B21 -> 980 | J11: 1 | K11: 37mm | O11: 75x50 | P11: =I11 -> 980 | Q11: =(P11*1.15)/1000 -> 1.127
G12: EXTERNAL HEAD LINER | H12: 17 X 102 | I12: =B21-204 -> 776 | J12: 1 | K12: N/A | O12: 125x60 | P12: =I11 -> 980 | Q12: =(P12*1.15)/1000 -> 1.127
A13: WITH HORNS TO TOP SASH ONLY | G13: INTERNAL HEAD LINER | H13: 17 X 85 | I13: =B21-170 -> 810 | J13: 1 | K13: N/A
G14: EXTERNAL JAMB LINER | H14: 17 X 102 | I14: =C21 -> 1825 | J14: 2 | K14: N/A
G15: INTERNAL JAMB LINER | H15: 17 X 86 | I15: =C21 -> 1825 | J15: 2 | K15: N/A
H16: Timber section | I16: Finished Length | J16: Number | K16: TENON LENGTH | L16: SLOT LENGTH | O16: RED GRANDIS
G17: TOP RAIL | H17: 57 X 57mm | I17: =B24 -> 802 | J17: 1 | K17: 39mm & 57mm | L17: N/A | O17: 63X63 | P17: =(I17*J17)+(I18*J18)+(I19*J19)+I21+I22 -> 6012 | Q17: =(P17*1.15)/1000 -> 6.9138
G18: STILES TOP SASH | H18: 57 X 57mm | I18: =D24 -> 920 | J18: 2 | K18: N/A | L18: TOP 39mm BOTTOM MORTICE | O18: 63X95 | P18: =I20 -> 802 | Q18: =(P18*1.1)/1000 -> 0.8822
B19: MID BAR | G19: STILES BOTTOM SASH | H19: 57 X 57mm | I19: =C25 -> 883 | J19: 2 | K19: N/A | L19: TOP 25mm BOTTOM 72mm
B20: FRAME WIDTH | C20: FRAME HEIGHT | G20: BOTTOM RAIL | H20: 57 X 90mm | I20: =B24 -> 802 | J20: 1 | K20: 39mm & 57mm | L20: N/A
B21: 980 | C21: 1825 | G21: TOP MEET RAIL | H21: 57 X 43mm | I21: =B24 -> 802 | J21: 1 | K21: 39mm & 57mm | L21: N/A
G22: BOTTOM MEET RAIL | H22: 57 X 43mm | I22: =B25 -> 802 | J22: 1 | K22: 39mm & 57mm | L22: N/A
B23: SASH WIDTH | C23: SASH HEIGHT | D23: SASH HEIGHT WITH HORN
A24: TOP SASH | B24: =B21-178 -> 802 | C24: =C21/2+(-62.5) -> 850 | D24: =C24+70 -> 920 | E24: 1no SASH | G24: TRICKLE VENT | H24: YES | I24: NO | J24: CONCEALED
A25: BOTTOM SASH | B25: =B21-178 -> 802 | C25: =C21/2+(-29.5) -> 883 | D25: N/A | E25: 1no SASH | G25: SASH CATCHES | H25: PAS24 | I25: NON PAS24
B26: GLASS WIDTH | C26: GLASS HEIGHT | G26: GLASS | H26: 24mm | I26: TGH/ARG/TGH | J26: Obscure | K26: Others?
B27: =B24-114+24 -> 712 | C27: =C24-100+24 -> 774 | D27: 1no UNIT | G27: GLASS | H27: 24.8mm | I27: LAM/ARG/TGH | J27: Obscure | K27: Others?
B28: =B25-114+24 -> 712 | C28: =C25-133+24 -> 774 | D28: 1no UNIT | G28: HARDWARE FINISH | H28: BRASS | I28: POL CHROME | J28: SATIN | K28: Others?
G29: CILL EXTENSION | H29: 35mm | I29: 60mm | J29: 85mm | K29: 110mm
G30: PAINT | H30: RAL | I30: ?
K32: TOTAL
G33: PRICE | H33: 1500 | I33: VAT 20% | J33: =H33*20% -> 300 | K33: =H33+J33 -> 1800

Sheet W-7
A4: GL07-JAM-B
B8: BOX SASH WINDOW | H8: Timber Section | I8: Finished Length | J8: Number | K8: TRENCH DEPTH | O8: Sapele
G9: HEAD | H9: 28 x 141 | I9: =B21 -> 580 | J9: 1 | K9: 11mm | O9: 1.5 inch x 150 | P9: =I9+(I10*2) -> 4018 | Q9: =(P9*1.15)/1000 -> 4.6207
G10: JAMBS | H10: 28 x 141 | I10: =C21-106 -> 1719 | J10: 2 | K10: N/A | O10: 1 inch x 120 | P10: =I12+I13+(I14*2)+(I15*2) -> 8086 | Q10: =(P10*1.15)/1000 -> 9.2989
G11: CILL | H11: 69 X 46/46.7 X 127 | I11: =B21 -> 580 | J11: 1 | K11: 37mm | O11: 75x50 | P11: =I11 -> 580 | Q11: =(P11*1.15)/1000 -> 0.667
G12: EXTERNAL HEAD LINER | H12: 17 X 102 | I12: =B21-204 -> 376 | J12: 1 | K12: N/A | O12: 125x60 | P12: =I11 -> 580 | Q12: =(P12*1.15)/1000 -> 0.667
A13: WITH HORNS TO TOP SASH ONLY | G13: INTERNAL HEAD LINER | H13: 17 X 85 | I13: =B21-170 -> 410 | J13: 1 | K13: N/A
G14: EXTERNAL JAMB LINER | H14: 17 X 102 | I14: =C21 -> 1825 | J14: 2 | K14: N/A
G15: INTERNAL JAMB LINER | H15: 17 X 86 | I15: =C21 -> 1825 | J15: 2 | K15: N/A
H16: Timber section | I16: Finished Length | J16: Number | K16: TENON LENGTH | L16: SLOT LENGTH | O16: RED GRANDIS
G17: TOP RAIL | H17: 57 X 57mm | I17: =B24 -> 402 | J17: 1 | K17: 39mm & 57mm | L17: N/A | O17: 63X63 | P17: =(I17*J17)+(I18*J18)+(I19*J19)+I21+I22 -> 4812 | Q17: =(P17*1.15)/1000 -> 5.5338
G18: STILES TOP SASH | H18: 57 X 57mm | I18: =D24 -> 920 | J18: 2 | K18: N/A | L18: TOP 39mm BOTTOM MORTICE | O18: 63X95 | P18: =I20 -> 402 | Q18: =(P18*1.1)/1000 -> 0.4422
B19: NON BAR | G19: STILES BOTTOM SASH | H19: 57 X 57mm | I19: =C25 -> 883 | J19: 2 | K19: N/A | L19: TOP 25mm BOTTOM 72mm
B20: FRAME WIDTH | C20: FRAME HEIGHT | G20: BOTTOM RAIL | H20: 57 X 90mm | I20: =B24 -> 402 | J20: 1 | K20: 39mm & 57mm | L20: N/A
B21: 580 | C21: 1825 | G21: TOP MEET RAIL | H21: 57 X 43mm | I21: =B24 -> 402 | J21: 1 | K21: 39mm & 57mm | L21: N/A
G22: BOTTOM MEET RAIL | H22: 57 X 43mm | I22: =B25 -> 402 | J22: 1 | K22: 39mm & 57mm | L22: N/A
B23: SASH WIDTH | C23: SASH HEIGHT | D23: SASH HEIGHT WITH HORN
A24: TOP SASH | B24: =B21-178 -> 402 | C24: =C21/2+(-62.5) -> 850 | D24: =C24+70 -> 920 | E24: 1no SASH | G24: TRICKLE VENT | H24: YES | I24: NO | J24: CONCEALED
A25: BOTTOM SASH | B25: =B21-178 -> 402 | C25: =C21/2+(-29.5) -> 883 | D25: N/A | E25: 1no SASH | G25: SASH CATCHES | H25: PAS24 | I25: NON PAS24
B26: GLASS WIDTH | C26: GLASS HEIGHT | G26: GLASS | H26: 24mm | I26: TGH/ARG/TGH | J26: Obscure | K26: Others?
B27: =B24-114+24 -> 312 | C27: =C24-100+24 -> 774 | D27: 1no UNIT | G27: GLASS | H27: 24.8mm | I27: LAM/ARG/TGH | J27: Obscure | K27: Others?
B28: =B25-114+24 -> 312 | C28: =C25-133+24 -> 774 | D28: 1no UNIT | G28: HARDWARE FINISH | H28: BRASS | I28: POL CHROME | J28: SATIN | K28: Others?
G29: CILL EXTENSION | H29: 35mm | I29: 60mm | J29: 85mm | K29: 110mm
G30: PAINT | H30: RAL | I30: ?
K32: TOTAL
G33: PRICE | H33: 1500 | I33: VAT 20% | J33: =H33*20% -> 300 | K33: =H33+J33 -> 1800

Sheet W-8
A1: 4 X SASH 32 WPA
A4: GL08-JAM -B
B8: BOX SASH WINDOW | H8: Timber Section | I8: Finished Length | J8: Number | K8: TRENCH DEPTH | O8: Sapele
G9: HEAD | H9: 28 x 141 | I9: =B21 -> 580 | J9: 1 | K9: 11mm | O9: 1.5 inch x 150 | P9: =I9+(I10*2) -> 4018 | Q9: =(P9*1.15)/1000 -> 4.6207
G10: JAMBS | H10: 28 x 141 | I10: =C21-106 -> 1719 | J10: 2 | K10: N/A | O10: 1 inch x 120 | P10: =I12+I13+(I14*2)+(I15*2) -> 8086 | Q10: =(P10*1.15)/1000 -> 9.2989
G11: CILL | H11: 69 X 46/46.7 X 127 | I11: =B21 -> 580 | J11: 1 | K11: 37mm | O11: 75x50 | P11: =I11 -> 580 | Q11: =(P11*1.15)/1000 -> 0.667
G12: EXTERNAL HEAD LINER | H12: 17 X 102 | I12: =B21-204 -> 376 | J12: 1 | K12: N/A | O12: 125x60 | P12: =I11 -> 580 | Q12: =(P12*1.15)/1000 -> 0.667
A13: WITH HORNS TO TOP SASH ONLY | G13: INTERNAL HEAD LINER | H13: 17 X 85 | I13: =B21-170 -> 410 | J13: 1 | K13: N/A
G14: EXTERNAL JAMB LINER | H14: 17 X 102 | I14: =C21 -> 1825 | J14: 2 | K14: N/A
G15: INTERNAL JAMB LINER | H15: 17 X 86 | I15: =C21 -> 1825 | J15: 2 | K15: N/A
H16: Timber section | I16: Finished Length | J16: Number | K16: TENON LENGTH | L16: SLOT LENGTH | O16: RED GRANDIS
G17: TOP RAIL | H17: 57 X 57mm | I17: =B24 -> 402 | J17: 1 | K17: 39mm & 57mm | L17: N/A | O17: 63X63 | P17: =(I17*J17)+(I18*J18)+(I19*J19)+I21+I22 -> 4812 | Q17: =(P17*1.15)/1000 -> 5.5338
G18: STILES TOP SASH | H18: 57 X 57mm | I18: =D24 -> 920 | J18: 2 | K18: N/A | L18: TOP 39mm BOTTOM MORTICE | O18: 63X95 | P18: =I20 -> 402 | Q18: =(P18*1.1)/1000 -> 0.4422
B19: NON BAR | G19: STILES BOTTOM SASH | H19: 57 X 57mm | I19: =C25 -> 883 | J19: 2 | K19: N/A | L19: TOP 25mm BOTTOM 72mm
B20: FRAME WIDTH | C20: FRAME HEIGHT | G20: BOTTOM RAIL | H20: 57 X 90mm | I20: =B24 -> 402 | J20: 1 | K20: 39mm & 57mm | L20: N/A
B21: 580 | C21: 1825 | G21: TOP MEET RAIL | H21: 57 X 43mm | I21: =B24 -> 402 | J21: 1 | K21: 39mm & 57mm | L21: N/A
G22: BOTTOM MEET RAIL | H22: 57 X 43mm | I22: =B25 -> 402 | J22: 1 | K22: 39mm & 57mm | L22: N/A
B23: SASH WIDTH | C23: SASH HEIGHT | D23: SASH HEIGHT WITH HORN
A24: TOP SASH | B24: =B21-178 -> 402 | C24: =C21/2+(-62.5) -> 850 | D24: =C24+70 -> 920 | E24: 1no SASH | G24: TRICKLE VENT | H24: YES | I24: NO | J24: CONCEALED
A25: BOTTOM SASH | B25: =B21-178 -> 402 | C25: =C21/2+(-29.5) -> 883 | D25: N/A | E25: 1no SASH | G25: SASH CATCHES | H25: PAS24 | I25: NON PAS24
B26: GLASS WIDTH | C26: GLASS HEIGHT | G26: GLASS | H26: 24mm | I26: TGH/ARG/TGH | J26: Obscure | K26: Others?
B27: =B24-114+24 -> 312 | C27: =C24-100+24 -> 774 | D27: 1no UNIT | G27: GLASS | H27: 24.8mm | I27: LAM/ARG/TGH | J27: Obscure | K27: Others?
B28: =B25-114+24 -> 312 | C28: =C25-133+24 -> 774 | D28: 1no UNIT | G28: HARDWARE FINISH | H28: BRASS | I28: POL CHROME | J28: SATIN | K28: Others?
G29: CILL EXTENSION | H29: 35mm | I29: 60mm | J29: 85mm | K29: 110mm
G30: PAINT | H30: RAL | I30: ?
K32: TOTAL
G33: PRICE | H33: 1500 | I33: VAT 20% | J33: =H33*20% -> 300 | K33: =H33+J33 -> 1800

Sheet W-9
A1: Jurek Kilvarock
A4: GL01-Kilv
B8: BOX SASH WINDOW | H8: Timber Section | I8: Finished Length | J8: Number | K8: TRENCH DEPTH | O8: Sapele
G9: HEAD | H9: 28 x 141 | I9: =B21 -> 1200 | J9: 1 | K9: 11mm | O9: 1.5 inch x 150 | P9: =I9+(I10*2) -> 4518 | Q9: =(P9*1.15)/1000 -> 5.1957
G10: JAMBS | H10: 28 x 141 | I10: =C21-106 -> 1659 | J10: 2 | K10: N/A | O10: 1 inch x 120 | P10: =I12+I13+(I14*2)+(I15*2) -> 9086 | Q10: =(P10*1.15)/1000 -> 10.4489
G11: CILL | H11: 69 X 46/46.7 X 127 | I11: =B21 -> 1200 | J11: 1 | K11: 37mm | O11: 75x50 | P11: =I11 -> 1200 | Q11: =(P11*1.15)/1000 -> 1.38
G12: EXTERNAL HEAD LINER | H12: 17 X 102 | I12: =B21-204 -> 996 | J12: 1 | K12: N/A | O12: 125x60 | P12: =I11 -> 1200 | Q12: =(P12*1.15)/1000 -> 1.38
A13: WITH HORNS TO TOP SASH ONLY | G13: INTERNAL HEAD LINER | H13: 17 X 85 | I13: =B21-170 -> 1030 | J13: 1 | K13: N/A
G14: EXTERNAL JAMB LINER | H14: 17 X 102 | I14: =C21 -> 1765 | J14: 2 | K14: N/A
G15: INTERNAL JAMB LINER | H15: 17 X 86 | I15: =C21 -> 1765 | J15: 2 | K15: N/A
H16: Timber section | I16: Finished Length | J16: Number | K16: TENON LENGTH | L16: SLOT LENGTH | O16: RED GRANDIS
G17: TOP RAIL | H17: 57 X 57mm | I17: =B26 -> 1022 | J17: 1 | K17: 39mm & 57mm | L17: N/A | O17: 63X63 | P17: =(I17*J17)+(I18*J18)+(I19*J19)+I21+I22 -> 6552 | Q17: =(P17*1.15)/1000 -> 7.5348
G18: STILES TOP SASH | H18: 57 X 57mm | I18: =D26 -> 890 | J18: 2 | K18: N/A | L18: TOP 39mm BOTTOM MORTICE | O18: 63X95 | P18: =I20 -> 1022 | Q18: =(P18*1.1)/1000 -> 1.1242
B19: NON BAR | G19: STILES BOTTOM SASH | H19: 57 X 57mm | I19: =C27 -> 853 | J19: 2 | K19: N/A | L19: TOP 25mm BOTTOM 72mm
B20: FRAME WIDTH | C20: FRAME HEIGHT | G20: BOTTOM RAIL | H20: 57 X 90mm | I20: =B26 -> 1022 | J20: 1 | K20: 39mm & 57mm | L20: N/A
B21: 1200 | C21: 1765 | G21: TOP MEET RAIL | H21: 57 X 43mm | I21: =B26 -> 1022 | J21: 1 | K21: 39mm & 57mm | L21: N/A
G22: BOTTOM MEET RAIL | H22: 57 X 43mm | I22: =B27 -> 1022 | J22: 1 | K22: 39mm & 57mm | L22: N/A
A24: TOP SASH | G24: TRICKLE VENT | H24: YES | I24: NO | J24: CONCEALED
A25: BOTTOM SASH | B25: SASH WIDTH | C25: SASH HEIGHT | D25: SASH HEIGHT WITH HORN | G25: SASH CATCHES | H25: PAS24 | I25: NON PAS24
B26: =B21-178 -> 1022 | C26: =C21/2+(-62.5) -> 820 | D26: =C26+70 -> 890 | E26: 1no SASH | G26: GLASS | H26: 24mm | I26: TGH/ARG/TGH | J26: Obscure | K26: Others?
B27: =B21-178 -> 1022 | C27: =C21/2+(-29.5) -> 853 | D27: N/A | E27: 1no SASH | G27: GLASS | H27: 24.8mm | I27: LAM/ARG/TGH | J27: Obscure | K27: Others?
B28: GLASS WIDTH | C28: GLASS HEIGHT | G28: HARDWARE FINISH | H28: BRASS | I28: POL CHROME | J28: SATIN | K28: Others?
B29: =B26-114+24 -> 932 | C29: =C26-100+24 -> 744 | D29: 1no UNIT | G29: CILL EXTENSION | H29: 35mm | I29: 60mm | J29: 85mm | K29: 110mm
B30: =B27-114+24 -> 932 | C30: =C27-133+24 -> 744 | D30: 1no UNIT | G30: PAINT | H30: RAL | I30: ?
K32: TOTAL
G33: PRICE | H33: 1500 | I33: VAT 20% | J33: =H33*20% -> 300 | K33: =H33+J33 -> 1800

Sheet W-10
A1: Jurek Kilvarock
A4: GL02-KILV
B8: BOX SASH WINDOW | H8: Timber Section | I8: Finished Length | J8: Number | K8: TRENCH DEPTH | O8: Sapele
G9: HEAD | H9: 28 x 141 | I9: =B21 -> 1080 | J9: 1 | K9: 11mm | O9: 1.5 inch x 150 | P9: =I9+(I10*2) -> 4118 | Q9: =(P9*1.15)/1000 -> 4.7357
G10: JAMBS | H10: 28 x 141 | I10: =C21-106 -> 1519 | J10: 2 | K10: N/A | O10: 1 inch x 120 | P10: =I12+I13+(I14*2)+(I15*2) -> 8286 | Q10: =(P10*1.15)/1000 -> 9.5289
G11: CILL | H11: 69 X 46/46.7 X 127 | I11: =B21 -> 1080 | J11: 1 | K11: 37mm | O11: 75x50 | P11: =I11 -> 1080 | Q11: =(P11*1.15)/1000 -> 1.242
G12: EXTERNAL HEAD LINER | H12: 17 X 102 | I12: =B21-204 -> 876 | J12: 1 | K12: N/A | O12: 125x60 | P12: =I11 -> 1080 | Q12: =(P12*1.15)/1000 -> 1.242
A13: WITH HORNS TO TOP SASH ONLY | G13: INTERNAL HEAD LINER | H13: 17 X 85 | I13: =B21-170 -> 910 | J13: 1 | K13: N/A
G14: EXTERNAL JAMB LINER | H14: 17 X 102 | I14: =C21 -> 1625 | J14: 2 | K14: N/A
G15: INTERNAL JAMB LINER | H15: 17 X 86 | I15: =C21 -> 1625 | J15: 2 | K15: N/A
H16: Timber section | I16: Finished Length | J16: Number | K16: TENON LENGTH | L16: SLOT LENGTH | O16: RED GRANDIS
G17: TOP RAIL | H17: 57 X 57mm | I17: =B24 -> 902 | J17: 1 | K17: 39mm & 57mm | L17: N/A | O17: 63X63 | P17: =(I17*J17)+(I18*J18)+(I19*J19)+I21+I22 -> 5912 | Q17: =(P17*1.15)/1000 -> 6.7988
G18: STILES TOP SASH | H18: 57 X 57mm | I18: =D24 -> 820 | J18: 2 | K18: N/A | L18: TOP 39mm BOTTOM MORTICE | O18: 63X95 | P18: =I20 -> 902 | Q18: =(P18*1.1)/1000 -> 0.9922
B19: NON BAR | G19: STILES BOTTOM SASH | H19: 57 X 57mm | I19: =C25 -> 783 | J19: 2 | K19: N/A | L19: TOP 25mm BOTTOM 72mm
B20: FRAME WIDTH | C20: FRAME HEIGHT | G20: BOTTOM RAIL | H20: 57 X 90mm | I20: =B24 -> 902 | J20: 1 | K20: 39mm & 57mm | L20: N/A
B21: 1080 | C21: 1625 | G21: TOP MEET RAIL | H21: 57 X 43mm | I21: =B24 -> 902 | J21: 1 | K21: 39mm & 57mm | L21: N/A
G22: BOTTOM MEET RAIL | H22: 57 X 43mm | I22: =B25 -> 902 | J22: 1 | K22: 39mm & 57mm | L22: N/A
B23: SASH WIDTH | C23: SASH HEIGHT | D23: SASH HEIGHT WITH HORN
A24: TOP SASH | B24: =B21-178 -> 902 | C24: =C21/2+(-62.5) -> 750 | D24: =C24+70 -> 820 | E24: 1no SASH | G24: TRICKLE VENT | H24: YES | I24: NO | J24: CONCEALED
A25: BOTTOM SASH | B25: =B21-178 -> 902 | C25: =C21/2+(-29.5) -> 783 | D25: N/A | E25: 1no SASH | G25: SASH CATCHES | H25: PAS24 | I25: NON PAS24
B26: GLASS WIDTH | C26: GLASS HEIGHT | G26: GLASS | H26: 24mm | I26: TGH/ARG/TGH | J26: Obscure | K26: Others?
B27: =B24-114+24 -> 812 | C27: =C24-100+24 -> 674 | D27: 1no UNIT | G27: GLASS | H27: 24.8mm | I27: LAM/ARG/TGH | J27: Obscure | K27: Others?
B28: =B25-114+24 -> 812 | C28: =C25-133+24 -> 674 | D28: 1no UNIT | G28: HARDWARE FINISH | H28: BRASS | I28: POL CHROME | J28: SATIN | K28: Others?
G29: CILL EXTENSION | H29: 35mm | I29: 60mm | J29: 85mm | K29: 110mm
G30: PAINT | H30: RAL | I30: ?
K32: TOTAL
G33: PRICE | H33: 1500 | I33: VAT 20% | J33: =H33*20% -> 300 | K33: =H33+J33 -> 1800

Sheet Timber Summary 
B9: Sapele | C9: lm
B10: 1.5 inch x 150 | C10: ='W-1'!Q9+'W-2'!Q9+'W-3'!Q9+'W-4'!Q9++'W-5'!Q9+'W-6'!Q9+'W-7'!Q9++'W-8'!Q9+'W-9'!Q9+'W-10'!Q9 -> 45.7355
B11: 1 inch x 120 | C11: ='W-1'!Q10+'W-2'!Q10+'W-3'!Q10+'W-4'!Q10++'W-5'!Q10+'W-6'!Q10+'W-7'!Q10++'W-8'!Q10+'W-9'!Q10+'W-10'!Q10 -> 92.046
B12: 75x50 | C12: ='W-1'!Q11+'W-2'!Q11+'W-3'!Q11+'W-4'!Q11++'W-5'!Q11+'W-6'!Q11+'W-7'!Q11++'W-8'!Q11+'W-9'!Q11+'W-10'!Q11 -> 10.649
B13: 125x60 | C13: ='W-1'!Q12+'W-2'!Q12+'W-3'!Q12+'W-4'!Q12++'W-5'!Q12+'W-6'!Q12+'W-7'!Q12++'W-8'!Q12+'W-9'!Q12+'W-10'!Q12 -> 10.649
B17: RED GRANDIS engineering | C17: lm | D17: 5.9 lm
B18: 63X63 | C18: ='W-1'!Q17+'W-2'!Q17+'W-3'!Q17+'W-4'!Q17++'W-5'!Q17+'W-6'!Q17+'W-7'!Q17++'W-8'!Q17+'W-9'!Q17+'W-10'!Q17 -> 62.8245 | D18: =C18/6 -> 10.47075 | E18: pcs
B19: 63X95 | C19: ='W-1'!Q18+'W-2'!Q18+'W-3'!Q18+'W-4'!Q18++'W-5'!Q18+'W-6'!Q18+'W-7'!Q18++'W-8'!Q18+'W-9'!Q18+'W-10'!Q18 -> 8.228 | D19: =C19/6 -> 1.3713333 | E19: pcs

Sheet Glazing summary 
D1: Width
D2: ='W-1'!B27 -> 652
B4: GL01-JAM
F6: ='W-1'!C27 -> 331.5
F7: High mm
B11: Width | C11: =D2 -> 652 | D11: Taoughten | E11: YES
B12: High | C12: =F6 -> 331.5 | D12: Frosted | E12: No
D13: Thickness | E13: 24mm | F13: 4x16x4
D14: Pcs | E14: 2
D15: Spacer colour | E15: White
D16: Width
D17: ='W-2'!B27 -> 802
B20: GL02-JAM
F21: ='W-2'!C27 -> 724
F22: High mm
B26: Width | C26: =D17 -> 802 | D26: Taoughten | E26: YES
B27: High | C27: =F21 -> 724 | D27: Frosted | E27: No
D28: Thickness | E28: 24mm | F28: 4x16x4
D29: Pcs | E29: 2
D30: Spacer colour | E30: White
D32: Width
D33: ='W-3'!B27 -> 782
B36: GL03-JAM
F37: ='W-3'!C27 -> 709
F38: High mm
B42: Width | C42: =D33 -> 782 | D42: Taoughten | E42: YES
B43: High | C43: =F37 -> 709 | D43: Frosted | E43: No
D44: Thickness | E44: 24mm | F44: 4x16x4
D45: Pcs | E45: 2
D46: Spacer colour | E46: White
D48: Width
D49: ='W-4'!B27 -> 972
B51: GL04-JAM
F53: ='W-4'!C27 -> 794
F54: High mm
B58: Width | C58: =D49 -> 972 | D58: Taoughten | E58: YES
B59: High | C59: =F53 -> 794 | D59: Frosted | E59: No
D60: Thickness | E60: 24mm | F60: 4x16x4
D61: Pcs | E61: 2
D62: Spacer colour | E62: White
...

Sheet Cutting list 
C5: ='W-1'!A4 -> GL01- CH/B | D5: ='W-2'!A4 -> GL02-JAM | E5: ='W-3'!A4 -> GL03-JAM | F5: ='W-4'!A4 -> GL04-JAM | G5: ='W-5'!A4 -> GL05-JAM | H5: ='W-6'!A4 -> GL06-JAM-B | I5: ='W-7'!A4 -> GL07-JAM-B | J5: GL08-JAM-B | K5: ='W-9'!A4 -> GL01-Kilv | L5: ='W-10'!A4 -> GL02-KILV | M5: TRENCH DEPTH
A6: 28x141 | B6: Head | C6: ='W-1'!I9 -> 920 | D6: ='W-2'!I9 -> 1070 | E6: ='W-3'!I9 -> 1050 | F6: ='W-4'!I9 -> 1240 | H6: ='W-6'!I9 -> 980 | I6: ='W-7'!I9 -> 580 | J6: ='W-8'!I9 -> 580 | K6: ='W-9'!I9 -> 1200 | L6: ='W-10'!I9 -> 1080 | M6: 11 mm
A7: 28x141 | B7: JAMBS L | C7: ='W-1'!I10 -> 834 | D7: ='W-2'!I10 -> 1619 | E7: ='W-3'!I10 -> 1589 | F7: ='W-4'!I10 -> 1759 | H7: ='W-6'!I10 -> 1719 | I7: ='W-7'!I10 -> 1719 | J7: ='W-8'!I10 -> 1719 | K7: ='W-9'!I10 -> 1659 | L7: ='W-10'!I10 -> 1519
A8: 28x141 | B8: JAMBS R | C8: ='W-1'!I10 -> 834 | D8: ='W-2'!I10 -> 1619 | E8: ='W-3'!I10 -> 1589 | F8: ='W-4'!I10 -> 1759 | H8: ='W-6'!I10 -> 1719 | I8: ='W-7'!I10 -> 1719 | J8: ='W-8'!I10 -> 1719 | K8: ='W-9'!I10 -> 1659 | L8: ='W-10'!I10 -> 1519
A9: 69x46 | B9: CILL 1 | C9: ='W-1'!I11 -> 920 | D9: ='W-2'!I11 -> 1070 | E9: ='W-3'!I11 -> 1050 | F9: ='W-4'!I11 -> 1240 | H9: ='W-6'!I11 -> 980 | I9: ='W-7'!I11 -> 580 | J9: ='W-8'!I11 -> 580 | K9: ='W-9'!I11 -> 1200 | L9: ='W-10'!I11 -> 1080 | M9: 37 mm
A10: ? | B10: CILL 2 | C10: ='W-1'!I11 -> 920 | D10: ='W-2'!I11 -> 1070 | E10: ='W-3'!I11 -> 1050 | F10: ='W-4'!I11 -> 1240 | H10: ='W-6'!I11 -> 980 | I10: ='W-7'!I11 -> 580 | J10: ='W-8'!I11 -> 580 | K10: ='W-9'!I11 -> 1200 | L10: ='W-10'!I11 -> 1080 | M10: 37 mm
A11: 17 x 102 | B11: INTERNAL HEAD LINEAR | C11: ='W-1'!I13 -> 750 | D11: ='W-2'!I13 -> 900 | E11: ='W-3'!I13 -> 880 | F11: ='W-4'!I13 -> 1070 | H11: ='W-6'!I13 -> 810 | I11: ='W-7'!I13 -> 410 | J11: ='W-8'!I13 -> 410 | K11: ='W-9'!I13 -> 1030 | L11: ='W-10'!I13 -> 910
A12: 17 x 85 | B12: EXT HEAD LINEAR | C12: ='W-1'!I12 -> 716 | D12: ='W-2'!I12 -> 866 | E12: ='W-3'!I12 -> 846 | F12: ='W-4'!I12 -> 1036 | H12: ='W-6'!I12 -> 776 | I12: ='W-7'!I12 -> 376 | J12: ='W-8'!I12 -> 376 | K12: ='W-9'!I12 -> 996 | L12: ='W-10'!I12 -> 876
A13: 17 x 101 | B13: EXTERNAL JAMB (L) | C13: ='W-1'!I14 -> 940 | D13: ='W-2'!I14 -> 1725 | E13: ='W-3'!I14 -> 1695 | F13: ='W-4'!I14 -> 1865 | H13: ='W-6'!I14 -> 1825 | I13: ='W-7'!I14 -> 1825 | J13: ='W-8'!I14 -> 1825 | K13: ='W-9'!I14 -> 1765 | L13: ='W-10'!I14 -> 1625
A14: 17 x 102 | B14: EXTERNAL JAMB (R) | C14: ='W-1'!I14 -> 940 | D14: ='W-2'!I14 -> 1725 | E14: ='W-3'!I14 -> 1695 | F14: ='W-4'!I14 -> 1865 | H14: ='W-6'!I14 -> 1825 | I14: ='W-7'!I14 -> 1825 | J14: ='W-8'!I14 -> 1825 | K14: ='W-9'!I14 -> 1765 | L14: ='W-10'!I14 -> 1625
A15: 17 x 86 | B15: INERNAL JAMB (L) | C15: ='W-1'!I15 -> 940 | D15: ='W-2'!I15 -> 1725 | E15: ='W-3'!I15 -> 1695 | F15: ='W-4'!I15 -> 1865 | H15: ='W-6'!I15 -> 1825 | I15: ='W-7'!I15 -> 1825 | J15: ='W-8'!I15 -> 1825 | K15: ='W-9'!I15 -> 1765 | L15: ='W-10'!I15 -> 1625
A16: 17 x 86 | B16: INTERNAL JAMB (R) | C16: ='W-1'!I15 -> 940 | D16: ='W-2'!I15 -> 1725 | E16: ='W-3'!I15 -> 1695 | F16: ='W-4'!I15 -> 1865 | H16: ='W-6'!I15 -> 1825 | I16: ='W-7'!I15 -> 1825 | J16: ='W-8'!I15 -> 1825 | K16: ='W-9'!I15 -> 1765 | L16: ='W-10'!I15 -> 1625
A21: Sash | M21: TENON LENGTH
A22: 57 X 57 | B22: TOP RAIL | C22: ='W-1'!I17 -> 742 | D22: ='W-2'!I17 -> 892 | E22: ='W-3'!I17 -> 872 | F22: ='W-4'!I17 -> 1062 | H22: ='W-6'!I17 -> 802 | I22: ='W-7'!I17 -> 402 | J22: ='W-8'!I17 -> 402 | K22: ='W-9'!I17 -> 1022 | L22: ='W-10'!I17 -> 902 | M22: 39 & 57 mm
A23: 57 X 57 | B23: STILES TOP SASH (L) | C23: ='W-1'!I18 -> 477.5 | D23: ='W-2'!I18 -> 870 | E23: ='W-3'!I18 -> 855 | F23: ='W-4'!I18 -> 940 | H23: ='W-6'!I18 -> 920 | I23: ='W-7'!I18 -> 920 | J23: ='W-8'!I18 -> 920 | K23: ='W-9'!I18 -> 890 | L23: ='W-10'!I18 -> 820
A24: 57 X 57 | B24: STILES TOP SASH (R) | C24: ='W-1'!I18 -> 477.5 | D24: ='W-2'!I18 -> 870 | E24: ='W-3'!I18 -> 855 | F24: ='W-4'!I18 -> 940 | H24: ='W-6'!I18 -> 920 | I24: ='W-7'!I18 -> 920 | J24: ='W-8'!I18 -> 920 | K24: ='W-9'!I18 -> 890 | L24: ='W-10'!I18 -> 820
A25: 57 X 57 | B25: STILES BOTTOM SASH (L) | C25: ='W-1'!I19 -> 440.5 | D25: ='W-2'!I19 -> 833 | E25: ='W-3'!I19 -> 818 | F25: ='W-4'!I19 -> 903 | H25: ='W-6'!I19 -> 883 | I25: ='W-7'!I19 -> 883 | J25: ='W-8'!I19 -> 883 | K25: ='W-9'!I19 -> 853 | L25: ='W-10'!I19 -> 783
A26: 57 X 57 | B26: STILES BOTTOM SASH (R) | C26: ='W-1'!I19 -> 440.5 | D26: ='W-2'!I19 -> 833 | E26: ='W-3'!I19 -> 818 | F26: ='W-4'!I19 -> 903 | H26: ='W-6'!I19 -> 883 | I26: ='W-7'!I19 -> 883 | J26: ='W-8'!I19 -> 883 | K26: ='W-9'!I19 -> 853 | L26: ='W-10'!I19 -> 783
A27: 57 X 90 | B27: BOTTOM RAIL | C27: ='W-1'!I20 -> 742 | D27: ='W-2'!I20 -> 892 | E27: ='W-3'!I20 -> 872 | F27: ='W-4'!I20 -> 1062 | H27: ='W-6'!I20 -> 802 | I27: ='W-7'!I20 -> 402 | J27: ='W-8'!I20 -> 402 | K27: ='W-9'!I20 -> 1022 | L27: ='W-10'!I20 -> 902 | M27: 39 & 57 mm
A28: 57 X 43 | B28: TOP MEET RAIL | C28: ='W-1'!I21 -> 742 | D28: ='W-2'!I21 -> 892 | E28: ='W-3'!I21 -> 872 | F28: ='W-4'!I21 -> 1062 | H28: ='W-6'!I21 -> 802 | I28: ='W-7'!I21 -> 402 | J28: ='W-8'!I21 -> 402 | K28: ='W-9'!I21 -> 1022 | L28: ='W-10'!I21 -> 902 | M28: 39 & 57 mm
A29: 57 X 43 | B29: BOTTOM MEET RAIL | C29: ='W-1'!I22 -> 742 | D29: ='W-2'!I22 -> 892 | E29: ='W-3'!I22 -> 872 | F29: ='W-4'!I22 -> 1062 | H29: ='W-6'!I22 -> 802 | I29: ='W-7'!I22 -> 402 | J29: ='W-8'!I22 -> 402 | K29: ='W-9'!I22 -> 1022 | L29: ='W-10'!I22 -> 902 | M29: 39 & 57 mm
